Workbook

Sheet Requerimientos
A1: Neptuno (Sistema de Gestión Documental) - ESPECIFICACIÓN DE REQUERIMIENTOS
A2: Código | B2: Tipo | C2: Categoría | D2: Nombre | E2: Descripción | F2: Historias asociadas
A3: RF-001 | B3: Funcional | C3: Autenticación y usuarios | D3: Iniciar sesión | E3: El sistema debe permitir al Usuario iniciar sesión con sus credenciales para acceder únicamente a lo que su perfil permite. | F3: =COUNTIF('Product Backlog'!$H$3:$H$87,"*"&A3&"*") -> 1
A4: RF-002 | B4: Funcional | C4: Autenticación y usuarios | D4: Cerrar sesión | E4: El sistema debe permitir al Usuario cerrar su sesión para evitar que otra persona use su cuenta en un equipo compartido. | F4: =COUNTIF('Product Backlog'!$H$3:$H$87,"*"&A4&"*") -> 1
A5: RF-003 | B5: Funcional | C5: Autenticación y usuarios | D5: Crear usuario | E5: El sistema debe permitir al Administrador crear un usuario (nombre, correo, área y estado) para dar acceso al sistema a un nuevo integrante de la organización. | F5: =COUNTIF('Product Backlog'!$H$3:$H$87,"*"&A5&"*") -> 1
A6: RF-004 | B6: Funcional | C6: Autenticación y usuarios | D6: Editar usuario | E6: El sistema debe permitir al Administrador editar los datos de un usuario existente (nombre, correo, área) para mantener su información actualizada. | F6: =COUNTIF('Product Backlog'!$H$3:$H$87,"*"&A6&"*") -> 1
A7: RF-005 | B7: Funcional | C7: Autenticación y usuarios | D7: Eliminar usuario | E7: El sistema debe permitir al Administrador eliminar un usuario mediante baja lógica para revocar su acceso sin perder su historial en la bitácora de auditoría. | F7: =COUNTIF('Product Backlog'!$H$3:$H$87,"*"&A7&"*") -> 1
A8: RF-006 | B8: Funcional | C8: Autenticación y usuarios | D8: Consultar y buscar usuarios | E8: El sistema debe permitir al Administrador consultar el listado de usuarios y filtrarlo por nombre, rol o estado para ubicar rápidamente al usuario que necesita administrar. | F8: =COUNTIF('Product Backlog'!$H$3:$H$87,"*"&A8&"*") -> 1
A9: RF-007 | B9: Funcional | C9: Roles y permisos | D9: Crear rol | E9: El sistema debe permitir al Administrador crear un rol (ej. Radicador, Tesorero, Gerente) para agrupar los permisos de un perfil de la organización. | F9: =COUNTIF('Product Backlog'!$H$3:$H$87,"*"&A9&"*") -> 1
A10: RF-008 | B10: Funcional | C10: Roles y permisos | D10: Editar rol | E10: El sistema debe permitir al Administrador editar el nombre y la descripción de un rol para mantenerlo alineado con la estructura de la organización. | F10: =COUNTIF('Product Backlog'!$H$3:$H$87,"*"&A10&"*") -> 1
A11: RF-009 | B11: Funcional | C11: Roles y permisos | D11: Eliminar rol | E11: El sistema debe permitir al Administrador eliminar un rol que ya no se use (sin usuarios asignados) para mantener limpio el catálogo de perfiles. | F11: =COUNTIF('Product Backlog'!$H$3:$H$87,"*"&A11&"*") -> 1
A12: RF-010 | B12: Funcional | C12: Roles y permisos | D12: Consultar roles | E12: El sistema debe permitir al Administrador consultar el listado de roles con sus permisos y usuarios asignados para tener visibilidad de quién puede hacer qué. | F12: =COUNTIF('Product Backlog'!$H$3:$H$87,"*"&A12&"*") -> 1
A13: RF-011 | B13: Funcional | C13: Roles y permisos | D13: Asignar permisos a un rol | E13: El sistema debe permitir al Administrador asignar o quitar permisos sobre funcionalidades a un rol para definir con precisión lo que puede hacer cada perfil. | F13: =COUNTIF('Product Backlog'!$H$3:$H$87,"*"&A13&"*") -> 1
A14: RF-012 | B14: Funcional | C14: Roles y permisos | D14: Asignar roles a un usuario | E14: El sistema debe permitir al Administrador asignar o quitar uno o varios roles a un usuario para determinar su nivel de acceso en el sistema. | F14: =COUNTIF('Product Backlog'!$H$3:$H$87,"*"&A14&"*") -> 1
... A87: RF-085 | B87: No funcional | C87: Requerimientos no funcionales | D87: Verificar la concurrencia de usuarios | E87: El sistema debe permitir al Equipo de desarrollo ejecutar pruebas de carga con el número mínimo de usuarios concurrentes (N por definir) para confirmar que no hay degradación del rendimiento. | F87: =COUNTIF('Product Backlog'!$H$3:$H$87,"*"&A87&"*") -> 1
D89: Total requerimientos funcionales | E89: =COUNTIF(B3:B87,"Funcional") -> 80
D90: Total requerimientos no funcionales | E90: =COUNTIF(B3:B87,"No funcional") -> 5
D91: Total general | E91: =E89+E90 -> 85

Sheet Product Backlog
A1: PRODUCT BACKLOG - HISTORIAS DE USUARIO PRIORIZADAS
A2: ID | B2: Épica | C2: Título | D2: Rol | E2: Historia de usuario | F2: Estimación (SP) | G2: Prioridad | H2: RF / RNF asociado | I2: Sprint | J2: Depende de | K2: Microservicio | L2: Método HTTP | M2: Endpoint estimado | N2: Permiso requerido (RBAC) | O2: Estado | P2: Observaciones
A3: HU-001 | B3: Autenticación y usuarios | C3: Iniciar sesión | D3: Usuario | E3: Como Usuario, quiero iniciar sesión con mis credenciales para acceder únicamente a lo que mi perfil permite. | F3: 2 | G3: Alta | H3: RF-001 | I3: SPRINT 1 | J3: Ninguna (historia base) | K3: ms-auth-catalogs | L3: POST POST GET | M3: /auth/login /auth/refrescar /auth/sesion | N3: Público / sesión | O3: Implementado | P3: Emite JWT de acceso (30 min) y de refresco (12 h).
A4: HU-002 | B4: Autenticación y usuarios | C4: Cerrar sesión | D4: Usuario | E4: Como Usuario, quiero cerrar mi sesión para evitar que otra persona use mi cuenta en un equipo compartido. | F4: 1 | G4: Media | H4: RF-002 | I4: SPRINT 1 | J4: HU-001 | K4: ms-auth-catalogs | L4: POST | M4: /auth/logout | N4: Sesión | O4: Implementado | P4: Revoca el token de acceso y el de refresco.
A5: HU-003 | B5: Autenticación y usuarios | C5: Crear usuario | D5: Administrador | E5: Como Administrador, quiero crear un usuario (nombre, correo, área y estado) para dar acceso al sistema a un nuevo integrante de la organización. | F5: 2 | G5: Alta | H5: RF-003 | I5: SPRINT 1 | J5: HU-001, HU-016 | K5: ms-auth-catalogs | L5: POST | M5: /usuarios | N5: usuarios:crear | O5: Implementado
A6: HU-004 | B6: Autenticación y usuarios | C6: Editar usuario | D6: Administrador | E6: Como Administrador, quiero editar los datos de un usuario existente (nombre, correo, área) para mantener su información actualizada. | F6: 1 | G6: Alta | H6: RF-004 | I6: SPRINT 1 | J6: HU-003 | K6: ms-auth-catalogs | L6: PUT PUT | M6: /usuarios/{id} /usuarios/{id}/clave | N6: usuarios:editar | O6: Implementado
A7: HU-005 | B7: Autenticación y usuarios | C7: Eliminar usuario | D7: Administrador | E7: Como Administrador, quiero eliminar un usuario mediante baja lógica para revocar su acceso sin perder su historial en la bitácora de auditoría. | F7: 1 | G7: Media | H7: RF-005 | I7: SPRINT 1 | J7: HU-003 | K7: ms-auth-catalogs | L7: DELETE | M7: /usuarios/{id} | N7: usuarios:eliminar | O7: Implementado | P7: Baja lógica; protege al último administrador.
A8: HU-006 | B8: Autenticación y usuarios | C8: Consultar y buscar usuarios | D8: Administrador | E8: Como Administrador, quiero consultar el listado de usuarios y filtrarlo por nombre, rol o estado para ubicar rápidamente al usuario que necesito administrar. | F8: 2 | G8: Media | H8: RF-006 | I8: SPRINT 1 | J8: HU-003 | K8: ms-auth-catalogs | L8: GET GET | M8: /usuarios?texto=&rolId=&estado=&areaId= /usuarios/{id} | N8: usuarios:consultar | O8: Implementado | P8: Paginado (pagina, tamano).
A9: HU-007 | B9: Roles y permisos | C9: Crear rol | D9: Administrador | E9: Como Administrador, quiero crear un rol (ej. Radicador, Tesorero, Gerente) para agrupar los permisos de un perfil de la organización. | F9: 1 | G9: Alta | H9: RF-007 | I9: SPRINT 1 | J9: Ninguna (historia base) | K9: ms-auth-catalogs | L9: POST | M9: /roles | N9: roles:crear | O9: Implementado
A10: HU-008 | B10: Roles y permisos | C10: Editar rol | D10: Administrador | E10: Como Administrador, quiero editar el nombre y la descripción de un rol para mantenerlo alineado con la estructura de la organización. | F10: 1 | G10: Alta | H10: RF-008 | I10: SPRINT 1 | J10: HU-007 | K10: ms-auth-catalogs | L10: PUT | M10: /roles/{id} | N10: roles:editar | O10: Implementado
A11: HU-009 | B11: Roles y permisos | C11: Eliminar rol | D11: Administrador | E11: Como Administrador, quiero eliminar un rol que ya no se use (sin usuarios asignados) para mantener limpio el catálogo de perfiles. | F11: 1 | G11: Media | H11: RF-009 | I11: SPRINT 1 | J11: HU-007 | K11: ms-auth-catalogs | L11: DELETE | M11: /roles/{id} | N11: roles:eliminar | O11: Implementado | P11: Solo roles sin usuarios asignados.
A12: HU-010 | B12: Roles y permisos | C12: Consultar roles | D12: Administrador | E12: Como Administrador, quiero consultar el listado de roles con sus permisos y usuarios asignados para tener visibilidad de quién puede hacer qué. | F12: 1 | G12: Media | H12: RF-010 | I12: SPRINT 1 | J12: HU-007 | K12: ms-auth-catalogs | L12: GET GET GET | M12: /roles /roles/{id} /roles/{id}/usuarios | N12: roles:consultar | O12: Implementado
A13: HU-011 | B13: Roles y permisos | C13: Asignar permisos a un rol | D13: Administrador | E13: Como Administrador, quiero asignar o quitar permisos sobre funcionalidades a un rol para definir con precisión lo que puede hacer cada perfil. | F13: 3 | G13: Alta | H13: RF-011 | I13: SPRINT 1 | J13: HU-007 | K13: ms-auth-catalogs | L13: GET PUT | M13: /permisos /roles/{id}/permisos | N13: roles:asignar-permisos | O13: Implementado | P13: Invalida los tokens de acceso de los usuarios del rol.
A14: HU-012 | B14: Roles y permisos | C14: Asignar roles a un usuario | D14: Administrador | E14: Como Administrador, quiero asignar o quitar uno o varios roles a un usuario para determinar su nivel de acceso en el sistema. | F14: 1 | G14: Alta | H14: RF-012 | I14: SPRINT 1 | J14: HU-003, HU-007 | K14: ms-auth-catalogs | L14: PUT | M14: /usuarios/{id}/roles | N14: usuarios:asignar-roles | O14: Implementado
A15: HU-013 | B15: Roles y permisos | C15: Restringir el acceso a funcionalidades por rol | D15: Sistema | E15: Como Sistema, quiero validar en cada solicitud los permisos del rol del usuario para impedir el acceso a funcionalidades no autorizadas. | F15: 3 | G15: Alta | H15: RF-013 | I15: SPRINT 1 | J15: HU-011, HU-012 | K15: ms-auth-catalogs | L15: — | M15: Transversal: filtro JWT + @PreAuthorize en cada endpoint | N15: — | O15: Implementado | P15: Cada microservicio valida el JWT y el permiso del endpoint.
A16: HU-014 | B16: Roles y permisos | C16: Restringir el acceso a documentos por rol | D16: Sistema | E16: Como Sistema, quiero limitar la visibilidad de los documentos según el rol y el área del usuario para proteger la información sensible. | F16: 3 | G16: Alta | H16: RF-014 | I16: SPRINT 1 | J16: HU-012, HU-016 | K16: ms-auth-catalogs | L16: GET GET | M16: /interno/usuarios/{id}/contexto-acceso /interno/usuarios/contextos | N16: Cabecera X-Servicio-Clave | O16: Implementado | P16: API interna: los demás servicios obtienen rol y área para filtrar documentos.
A17: HU-015 | B17: Radicación documental | C17: Administrar catálogo de tipos documentales | D17: Administrador | E17: Como Administrador, quiero crear, editar y desactivar los tipos documentales (Factura, Orden de compra, Contrato, etc.) para clasificar correctamente cada radicado. | F17: 1 | G17: Alta | H17: RF-015 | I17: SPRINT 2 | J17: Ninguna (historia base) | K17: ms-auth-catalogs | L17: GET POST PUT DELETE | M17: /tipos-documentales /tipos-documentales /tipos-documentales/{id} /tipos-documentales/{id} | N17: catalogos:consultar / catalogos:administrar | O17: Implementado | P17: DELETE desactiva, no borra.
A18: HU-016 | B18: Radicación documental | C18: Administrar catálogo de áreas | D18: Administrador | E18: Como Administrador, quiero crear, editar y desactivar las áreas de la organización para asignar cada documento y cada usuario al área que corresponde. | F18: 1 | G18: Alta | H18: RF-016 | I18: SPRINT 1 | J18: Ninguna (historia base) | K18: ms-auth-catalogs | L18: GET POST PUT DELETE | M18: /areas /areas /areas/{id} /areas/{id} | N18: catalogos:consultar / catalogos:administrar | O18: Implementado | P18: DELETE desactiva, no borra.
A19: HU-017 | B19: Radicación documental | C19: Registrar radicado con consecutivo único | D19: Radicador | E19: Como Radicador, quiero registrar un documento en el sistema para que se le asigne automáticamente un código de radicado único e inmutable con el formato AAAAMMDD + X + CONSECUTIVO, donde X identifica el origen del documento (1 = Interno, 2 = Externo, 3 = Recibido, 4 = No radicable). | F19: 3 | G19: Alta | H19: RF-017 | I19: SPRINT 1 | J19: HU-015, HU-016, HU-022 | K19: ms-document-management | L19: POST | M19: /radicados | N19: radicados:crear | O19: Pendiente | P19: El servidor genera el código AAAAMMDD+X+consecutivo; publica radicado.creado.
A20: HU-018 | B20: Radicación documental | C20: Clasificar el radicado por origen | D20: Radicador | E20: Como Radicador, quiero clasificar el documento como Interno, Externo, Recibido o No radicable al radicarlo, habilitando los campos correspondientes según el origen seleccionado, para identificar de dónde proviene y qué requisitos de radicación aplican. | F20: 1 | G20: Alta | H20: RF-018 | I20: SPRINT 1 | J20: HU-017 | K20: ms-document-management | L20: POST | M20: /radicados | N20: radicados:crear | O20: Pendiente | P20: Campo origen (INTERNO, EXTERNO, RECIBIDO, NO_RADICABLE); catálogo en GET /api/usuarios/catalogos/origenes.
A21: HU-019 | B21: Radicación documental | C21: Capturar metadatos obligatorios | D21: Radicador | E21: Como Radicador, quiero diligenciar los metadatos obligatorios (título, fecha, resumen, tipo documental y área encargada) para que el documento quede correctamente descrito, sin permitir guardar con campos vacíos. | F21: 2 | G21: Alta | H21: RF-019 | I21: SPRINT 1 | J21: HU-017 | K21: ms-document-management | L21: POST PUT | M21: /radicados /radicados/{id} | N21: radicados:crear | O21: Pendiente | P21: Valida obligatorios: 400 DATOS_INVALIDOS con el detalle por campo.
A22: HU-020 | B22: Radicación documental | C22: Consultar el detalle de un radicado | D22: Usuario operativo | E22: Como Usuario operativo, quiero consultar el detalle de un radicado (metadatos, anexos y estado actual) para conocer toda la información del documento. | F22: 1 | G22: Alta | H22: RF-020 | I22: SPRINT 1 | J22: HU-017 | K22: ms-document-management | L22: GET | M22: /radicados/{id} | N22: radicados:consultar (nuevo) | O22: Pendiente | P22: Incluye metadatos, anexos y estado del trámite.
A23: HU-021 | B23: Radicación documental | C23: Editar metadatos de un radicado | D23: Radicador | E23: Como Radicador, quiero editar los metadatos de un radicado sin alterar su código para corregir errores de captura. | F23: 1 | G23: Media | H23: RF-021 | I23: SPRINT 2 | J23: HU-017, HU-019 | K23: ms-document-management | L23: PATCH | M23: /radicados/{id}/metadatos | N23: radicados:editar | O23: Pendiente | P23: El código del radicado es inmutable.
A24: HU-022 | B24: Radicación documental | C24: Administrar entidades | D24: Radicador | E24: Como Radicador, quiero crear y consultar las entidades (NIT y Razón social) requeridas para radicar documentos de origen Recibido o para la generación de documentos de origen Externo. | F24: 1 | G24: Media | H24: RF-022 | I24: SPRINT 3 | J24: Ninguna (historia base) | K24: ms-auth-catalogs | L24: GET POST PUT DELETE | M24: /entidades?texto= /entidades /entidades/{id} /entidades/{id} | N24: catalogos:consultar / catalogos:administrar | O24: Implementado | P24: DELETE desactiva, no borra.
A25: HU-023 | B25: Radicación documental | C25: Listar y filtrar radicados | D25: Usuario operativo | E25: Como Usuario operativo, quiero listar los radicados y filtrarlos por código, fecha, origen, tipo documental y área para encontrar rápidamente un documento. | F25: 2 | G25: Alta | H25: RF-023 | I25: SPRINT 3 | J25: HU-017 | K25: ms-document-management | L25: GET | M25: /radicados?codigo=&desde=&hasta=&origen=&tipoId=&areaId= | N25: radicados:consultar (nuevo) | O25: Pendiente | P25: Paginado y filtrado por rol/área (HU-014).
A26: HU-024 | B26: Radicación documental | C26: Restringir la radicación de Recibidos al rol Radicador | D26: Sistema | E26: Como Sistema, quiero permitir que únicamente los usuarios con rol Radicador registren documentos cuyo origen sea Recibido para garantizar que la radicación de correspondencia externa la realice el personal autorizado. | F26: 2 | G26: Alta | H26: RF-024 | I26: SPRINT 1 | J26: HU-012, HU-018 | K26: ms-document-management | L26: POST | M26: /radicados | N26: radicados:radicar-recibido | O26: Pendiente | P26: Regla: origen RECIBIDO exige el permiso; si falta, 403.
... A32: HU-030 | B32: Archivo y Expediente | C32: Crear estructura de carpetas por Área | D32: Administrador | E32: Como Administrador, quiero crear y organizar las carpetas principales del expediente asociadas a cada área de la empresa para estructurar el archivo institucional por área. | F32: 2 | G32: Alta | H32: RF-030 | I32: SPRINT 3 | J32: HU-016 | K32: ms-document-management | L32: POST GET | M32: /carpetas /carpetas?areaId= | N32: expediente:administrar (nuevo) | O32: Pendiente | P32: Una carpeta raíz por área.
A33: HU-031 | B33: Archivo y Expediente | C33: Crear subcarpetas por Tipo de Expediente | D33: Administrador | E33: Como Administrador, quiero crear subcarpetas temáticas dentro de la carpeta de un área para clasificar los documentos del expediente según su tipo. | F33: 2 | G33: Alta | H33: RF-031 | I33: SPRINT 3 | J33: HU-030 | K33: ms-document-management | L33: POST | M33: /carpetas/{id}/subcarpetas | N33: expediente:administrar (nuevo) | O33: Pendiente
A34: HU-032 | B34: Archivo y Expediente | C34: Consultar Expediente Central | D34: Usuario operativo | E34: Como Usuario operativo, quiero visualizar el expediente central en una vista de árbol con sus carpetas y documentos originales almacenados para ubicar y consultar rápidamente cualquier documento archivado. | F34: 3 | G34: Alta | H34: RF-032 | I34: SPRINT 3 | J34: HU-030, HU-031 | K34: ms-document-management | L34: GET GET | M34: /expediente/arbol /carpetas/{id}/documentos | N34: expediente:ver | O34: Pendiente
A35: HU-033 | B35: Archivo y Expediente | C35: Restringir acceso al Expediente por Rol (RBAC) | D35: Sistema | E35: Como Sistema, quiero filtrar la visibilidad de las carpetas y subcarpetas del expediente según los permisos del rol del usuario para proteger la información de cada área. | F35: 2 | G35: Alta | H35: RF-033 | I35: SPRINT 3 | J35: HU-012, HU-032 | K35: ms-document-management | L35: GET | M35: /expediente/arbol | N35: expediente:ver | O35: Pendiente | P35: Regla: filtra carpetas con el contexto de /interno/usuarios/{id}/contexto-acceso.
A36: HU-034 | B36: Archivo y Expediente | C36: Cargar documento directo al Expediente (No radicable) | D36: Radicador | E36: Como Radicador, quiero subir un documento de origen No radicable directamente a una subcarpeta del expediente, asignándole su consecutivo correspondiente, para archivar soportes que no requieren trámite de flujo. | F36: 2 | G36: Media | H36: RF-034 | I36: SPRINT 3 | J36: HU-017, HU-031 | K36: ms-document-management | L36: POST | M36: /carpetas/{id}/documentos | N36: expediente:cargar (nuevo) | O36: Pendiente | P36: Documento No radicable con consecutivo propio de la carpeta.
A37: HU-035 | B37: Plantillas y Generación Documental | C37: Cargar plantilla con variables | D37: Administrador | E37: Como Administrador, quiero subir un archivo de plantilla al sistema y definir sus etiquetas o variables dinámicas para reutilizarlo en la generación de documentos. | F37: 3 | G37: Alta | H37: RF-035 | I37: SPRINT 3 | J37: Ninguna (historia base) | K37: ms-document-management | L37: POST GET PUT | M37: /plantillas /plantillas /plantillas/{id}/variables | N37: plantillas:administrar (nuevo) | O37: Pendiente | P37: Plantilla DOCX guardada en MinIO.
A38: HU-036 | B38: Plantillas y Generación Documental | C38: Asociar plantilla a tipo de origen | D38: Administrador | E38: Como Administrador, quiero vincular una plantilla únicamente a los orígenes Interno o Externo para que solo esté disponible en los trámites correspondientes. | F38: 1 | G38: Media | H38: RF-036 | I38: SPRINT 3 | J38: HU-035, HU-018 | K38: ms-document-management | L38: PUT | M38: /plantillas/{id}/origenes | N38: plantillas:administrar (nuevo) | O38: Pendiente | P38: Solo orígenes INTERNO y EXTERNO.
A39: HU-037 | B39: Plantillas y Generación Documental | C39: Renderizar datos en plantilla | D39: Radicador | E39: Como Radicador, quiero que el sistema reemplace automáticamente las variables de la plantilla elegida con los metadatos que ingreso para generar el documento sin diligenciarlo manualmente. | F39: 3 | G39: Alta | H39: RF-037 | I39: SPRINT 3 | J39: HU-019, HU-035, HU-036 | K39: ms-document-management | L39: POST | M39: /plantillas/{id}/render | N39: plantillas:usar (nuevo) | O39: Pendiente | P39: Cuerpo: radicadoId; devuelve vista previa con las variables reemplazadas.
A40: HU-038 | B40: Plantillas y Generación Documental | C40: Generar y exportar PDF desde plantilla | D40: Radicador | E40: Como Radicador, quiero convertir el documento renderizado en un archivo PDF final para dejarlo listo y radicarlo en el sistema. | F40: 2 | G40: Alta | H40: RF-038 | I40: SPRINT 3 | J40: HU-037 | K40: ms-document-management | L40: POST GET | M40: /radicados/{id}/pdf /radicados/{id}/pdf | N40: plantillas:usar (nuevo) | O40: Pendiente | P40: Genera el PDF final y lo guarda como anexo.
A41: HU-039 | B41: Orígenes y Manejo de Copias | C41: Capturar metadatos extendidos | D41: Radicador | E41: Como Radicador, quiero registrar metadatos extendidos (NIT, Entidad, Área, Nombre de carpeta y Comentarios) al radicar un documento para complementar la información base según el tipo de trámite. | F41: 2 | G41: Alta | H41: RF-039 | I41: SPRINT 3 | J41: HU-019, HU-022 | K41: ms-document-management | L41: PUT | M41: /radicados/{id}/metadatos-extendidos | N41: radicados:editar | O41: Pendiente | P41: NIT/entidad, área, carpeta y comentarios.
A42: HU-040 | B42: Orígenes y Manejo de Copias | C42: Clasificar documento por Clase (Original/Copia) | D42: Radicador | E42: Como Radicador, quiero asignar el atributo de Clase (Original o Copia) a cada documento para diferenciar la pieza principal del trámite de sus duplicados. | F42: 1 | G42: Alta | H42: RF-040 | I42: SPRINT 3 | J42: HU-017 | K42: ms-document-management | L42: PATCH | M42: /radicados/{id}/clase | N42: radicados:clase | O42: Pendiente | P42: ORIGINAL o COPIA.
A43: HU-041 | B43: Orígenes y Manejo de Copias | C43: Enviar copias informativas a múltiples usuarios | D43: Radicador | E43: Como Radicador, quiero seleccionar uno o varios destinatarios para enviarles un duplicado (Clase = Copia) de un documento para mantenerlos informados sin alterar el trámite original. | F43: 2 | G43: Media | H43: RF-041 | I43: SPRINT 3 | J43: HU-040, HU-003 | K43: ms-document-management | L43: POST | M43: /radicados/{id}/copias | N43: radicados:editar | O43: Pendiente | P43: Cuerpo: destinatarios[]; publica copia.enviada.
A44: HU-042 | B44: Orígenes y Manejo de Copias | C44: Visualizar copias en bandeja secundaria | D44: Usuario operativo | E44: Como Usuario operativo, quiero ver las copias que he recibido en una sección separada de mi bandeja de entrada para consultarlas sin bloquear el avance del radicado original. | F44: 2 | G44: Media | H44: RF-042 | I44: SPRINT 3 | J44: HU-041 | K44: ms-document-management | L44: GET PATCH | M44: /copias/recibidas /copias/{id}/leida | N44: Sesión (solo las propias) | O44: Pendiente
A45: HU-043 | B45: Bitácora y auditoría | C45: Registrar eventos en la bitácora | D45: Sistema | E45: Como Sistema, quiero registrar en la bitácora cada acción realizada sobre un documento (quién, qué y fecha/hora) para garantizar la trazabilidad completa. | F45: 3 | G45: Media | H45: RF-043 | I45: SPRINT 3 | J45: HU-001 | K45: ms-audit-infra | L45: AMQP | M45: Consume la cola audit.infrastructure (exchange neptuno.eventos) | N45: — | O45: Pendiente | P45: Los demás servicios publican con patrón outbox (ya lo hace ms-auth-catalogs).
...

Sheet Microservicios
A1: DISTRIBUCIÓN DE HISTORIAS POR MICROSERVICIO
A2: Microservicio | B2: Dominio / responsabilidad | C2: Tecnología | D2: Base de datos | E2: Prefijo de la API | F2: Historias (HU) | G2: Story Points | H2: HU implementadas | I2: % implementado
A3: ms-auth-catalogs | B3: Autenticación, Seguridad y Datos Maestros | C3: Java 21 · Spring Boot | D3: auth_catalogs_db | E3: /api/usuarios | F3: =COUNTIF('Product Backlog'!$K$3:$K$87,$A3) -> 17 | G3: =SUMIF('Product Backlog'!$K$3:$K$87,$A3,'Product Backlog'!$F$3:$F$87) -> 26 | H3: =COUNTIFS('Product Backlog'!$K$3:$K$87,$A3,'Product Backlog'!$O$3:$O$87,"Implementado") -> 17 | I3: =IF(F3=0,0,H3/F3) -> 1
A4: ms-document-management | B4: Gestión Documental, Radicación y Archivo | C4: Node.js · Express | D4: document_management_db | E4: /api/documentos | F4: =COUNTIF('Product Backlog'!$K$3:$K$87,$A4) -> 25 | G4: =SUMIF('Product Backlog'!$K$3:$K$87,$A4,'Product Backlog'!$F$3:$F$87) -> 45 | H4: =COUNTIFS('Product Backlog'!$K$3:$K$87,$A4,'Product Backlog'!$O$3:$O$87,"Implementado") -> 0 | I4: =IF(F4=0,0,H4/F4) -> 0
A5: ms-workflow-bpm | B5: Motor BPM y Bandeja de Tareas | C5: Node.js · NestJS | D5: workflow_bpm_db | E5: /api/flujos | F5: =COUNTIF('Product Backlog'!$K$3:$K$87,$A5) -> 34 | G5: =SUMIF('Product Backlog'!$K$3:$K$87,$A5,'Product Backlog'!$F$3:$F$87) -> 60 | H5: =COUNTIFS('Product Backlog'!$K$3:$K$87,$A5,'Product Backlog'!$O$3:$O$87,"Implementado") -> 0 | I5: =IF(F5=0,0,H5/F5) -> 0
A6: ms-audit-infra | B6: Bitácora Transversal y Requerimientos No Funcionales | C6: Go | D6: audit_infra_db | E6: /api/auditoria | F6: =COUNTIF('Product Backlog'!$K$3:$K$87,$A6) -> 9 | G6: =SUMIF('Product Backlog'!$K$3:$K$87,$A6,'Product Backlog'!$F$3:$F$87) -> 16 | H6: =COUNTIFS('Product Backlog'!$K$3:$K$87,$A6,'Product Backlog'!$O$3:$O$87,"Implementado") -> 0 | I6: =IF(F6=0,0,H6/F6) -> 0
A7: Total | F7: =SUM(F3:F6) -> 85 | G7: =SUM(G3:G6) -> 147 | H7: =SUM(H3:H6) -> 17 | I7: =IF(F7=0,0,H7/F7) -> 0.2
A9: Notas
A10: Fuente de la asignación: documento Neptuno_Proyecto.docx, sección "Arquitectura de Microservicios y Distribución" (17 + 25 + 34 + 9 = 85 HU).
A11: Los endpoints de la hoja Product Backlog son estimaciones y se escriben relativos al prefijo de su microservicio: p. ej. POST /radicados = POST /api/documentos/radicados.
A12: Los de ms-auth-catalogs (estado Implementado) son los reales del código en servicio-usuarios/.
A13: Un permiso marcado "(nuevo)" todavía no existe en el catálogo de ms-auth-catalogs y habría que agregarlo a CatalogoPermisos.
A14: AMQP = la historia se resuelve consumiendo eventos de RabbitMQ, no con un endpoint REST. "—" = regla transversal o requisito sin endpoint propio.

Sheet Sprints
A1: PLANTEAMIENTO INICIAL DE SPRINTS - 4 SPRINTS DE 2 SEMANAS
A2: Sprint | B2: Objetivo del sprint | C2: Historia / Actividad | D2: Descripción | E2: SP
A3: SPRINT 1 | B3: Arquitectura base, RBAC y radicación básica Disponer del núcleo del sistema (base de datos, seguridad y control de acceso) y permitir la radicación de documentos con sus metadatos base y anexos, aplicando el formato de radicado AAAAMMDD+X+consecutivo y la restricción de que solo los Radicadores radiquen documentos Recibidos, dejando lista la bitácora de auditoría. | C3: HU-001 | D3: {=INDEX('Product Backlog'!$C$3:$C$87,MATCH($C3,'Product Backlog'!$A$3:$A$87,0))} -> Iniciar sesión | E3: {=INDEX('Product Backlog'!$F$3:$F$87,MATCH($C3,'Product Backlog'!$A$3:$A$87,0))} -> 2
C4: HU-002 | D4: {=INDEX('Product Backlog'!$C$3:$C$87,MATCH($C4,'Product Backlog'!$A$3:$A$87,0))} -> Cerrar sesión | E4: {=INDEX('Product Backlog'!$F$3:$F$87,MATCH($C4,'Product Backlog'!$A$3:$A$87,0))} -> 1
C5: HU-003 | D5: {=INDEX('Product Backlog'!$C$3:$C$87,MATCH($C5,'Product Backlog'!$A$3:$A$87,0))} -> Crear usuario | E5: {=INDEX('Product Backlog'!$F$3:$F$87,MATCH($C5,'Product Backlog'!$A$3:$A$87,0))} -> 2
C6: HU-004 | D6: {=INDEX('Product Backlog'!$C$3:$C$87,MATCH($C6,'Product Backlog'!$A$3:$A$87,0))} -> Editar usuario | E6: {=INDEX('Product Backlog'!$F$3:$F$87,MATCH($C6,'Product Backlog'!$A$3:$A$87,0))} -> 1
C7: HU-005 | D7: {=INDEX('Product Backlog'!$C$3:$C$87,MATCH($C7,'Product Backlog'!$A$3:$A$87,0))} -> Eliminar usuario | E7: {=INDEX('Product Backlog'!$F$3:$F$87,MATCH($C7,'Product Backlog'!$A$3:$A$87,0))} -> 1
C8: HU-006 | D8: {=INDEX('Product Backlog'!$C$3:$C$87,MATCH($C8,'Product Backlog'!$A$3:$A$87,0))} -> Consultar y buscar usuarios | E8: {=INDEX('Product Backlog'!$F$3:$F$87,MATCH($C8,'Product Backlog'!$A$3:$A$87,0))} -> 2
C9: HU-007 | D9: {=INDEX('Product Backlog'!$C$3:$C$87,MATCH($C9,'Product Backlog'!$A$3:$A$87,0))} -> Crear rol | E9: {=INDEX('Product Backlog'!$F$3:$F$87,MATCH($C9,'Product Backlog'!$A$3:$A$87,0))} -> 1
C10: HU-008 | D10: {=INDEX('Product Backlog'!$C$3:$C$87,MATCH($C10,'Product Backlog'!$A$3:$A$87,0))} -> Editar rol | E10: {=INDEX('Product Backlog'!$F$3:$F$87,MATCH($C10,'Product Backlog'!$A$3:$A$87,0))} -> 1
C11: HU-009 | D11: {=INDEX('Product Backlog'!$C$3:$C$87,MATCH($C11,'Product Backlog'!$A$3:$A$87,0))} -> Eliminar rol | E11: {=INDEX('Product Backlog'!$F$3:$F$87,MATCH($C11,'Product Backlog'!$A$3:$A$87,0))} -> 1
C12: HU-010 | D12: {=INDEX('Product Backlog'!$C$3:$C$87,MATCH($C12,'Product Backlog'!$A$3:$A$87,0))} -> Consultar roles | E12: {=INDEX('Product Backlog'!$F$3:$F$87,MATCH($C12,'Product Backlog'!$A$3:$A$87,0))} -> 1
C13: HU-011 | D13: {=INDEX('Product Backlog'!$C$3:$C$87,MATCH($C13,'Product Backlog'!$A$3:$A$87,0))} -> Asignar permisos a un rol | E13: {=INDEX('Product Backlog'!$F$3:$F$87,MATCH($C13,'Product Backlog'!$A$3:$A$87,0))} -> 3
C14: HU-012 | D14: {=INDEX('Product Backlog'!$C$3:$C$87,MATCH($C14,'Product Backlog'!$A$3:$A$87,0))} -> Asignar roles a un usuario | E14: {=INDEX('Product Backlog'!$F$3:$F$87,MATCH($C14,'Product Backlog'!$A$3:$A$87,0))} -> 1
C15: HU-013 | D15: {=INDEX('Product Backlog'!$C$3:$C$87,MATCH($C15,'Product Backlog'!$A$3:$A$87,0))} -> Restringir el acceso a funcionalidades por rol | E15: {=INDEX('Product Backlog'!$F$3:$F$87,MATCH($C15,'Product Backlog'!$A$3:$A$87,0))} -> 3
... C26: HU-024 | D26: {=INDEX('Product Backlog'!$C$3:$C$87,MATCH($C26,'Product Backlog'!$A$3:$A$87,0))} -> Restringir la radicación de Recibidos al rol Radicador | E26: {=INDEX('Product Backlog'!$F$3:$F$87,MATCH($C26,'Product Backlog'!$A$3:$A$87,0))} -> 2
C27: Total SPRINT 1 | E27: =SUM(E3:E26) -> 39
A29: SPRINT 2 | B29: Motor de flujos (workflow engine) y bandeja de tareas Permitir el diseño y la publicación de flujos lineales de aprobación e integrar la bandeja de entrada para que las áreas operativas aprueben, rechacen o devuelvan documentos. | C29: HU-015 | D29: {=INDEX('Product Backlog'!$C$3:$C$87,MATCH($C29,'Product Backlog'!$A$3:$A$87,0))} -> Administrar catálogo de tipos documentales | E29: {=INDEX('Product Backlog'!$F$3:$F$87,MATCH($C29,'Product Backlog'!$A$3:$A$87,0))} -> 1
C30: HU-021 | D30: {=INDEX('Product Backlog'!$C$3:$C$87,MATCH($C30,'Product Backlog'!$A$3:$A$87,0))} -> Editar metadatos de un radicado | E30: {=INDEX('Product Backlog'!$F$3:$F$87,MATCH($C30,'Product Backlog'!$A$3:$A$87,0))} -> 1
C31: HU-027 | D31: {=INDEX('Product Backlog'!$C$3:$C$87,MATCH($C31,'Product Backlog'!$A$3:$A$87,0))} -> Adjuntar múltiples archivos en una sola carga | E31: {=INDEX('Product Backlog'!$F$3:$F$87,MATCH($C31,'Product Backlog'!$A$3:$A$87,0))} -> 1
C32: HU-029 | D32: {=INDEX('Product Backlog'!$C$3:$C$87,MATCH($C32,'Product Backlog'!$A$3:$A$87,0))} -> Eliminar un anexo | E32: {=INDEX('Product Backlog'!$F$3:$F$87,MATCH($C32,'Product Backlog'!$A$3:$A$87,0))} -> 1
C33: HU-046 | D33: {=INDEX('Product Backlog'!$C$3:$C$87,MATCH($C33,'Product Backlog'!$A$3:$A$87,0))} -> Consultar el historial de un documento | E33: {=INDEX('Product Backlog'!$F$3:$F$87,MATCH($C33,'Product Backlog'!$A$3:$A$87,0))} -> 2
C34: HU-049 | D34: {=INDEX('Product Backlog'!$C$3:$C$87,MATCH($C34,'Product Backlog'!$A$3:$A$87,0))} -> Editar un flujo de trabajo | E34: {=INDEX('Product Backlog'!$F$3:$F$87,MATCH($C34,'Product Backlog'!$A$3:$A$87,0))} -> 1
C35: HU-050 | D35: {=INDEX('Product Backlog'!$C$3:$C$87,MATCH($C35,'Product Backlog'!$A$3:$A$87,0))} -> Desactivar un flujo de trabajo | E35: {=INDEX('Product Backlog'!$F$3:$F$87,MATCH($C35,'Product Backlog'!$A$3:$A$87,0))} -> 1
C36: HU-052 | D36: {=INDEX('Product Backlog'!$C$3:$C$87,MATCH($C36,'Product Backlog'!$A$3:$A$87,0))} -> Visualizar el flujo en un lienzo gráfico | E36: {=INDEX('Product Backlog'!$F$3:$F$87,MATCH($C36,'Product Backlog'!$A$3:$A$87,0))} -> 5
C37: HU-053 | D37: {=INDEX('Product Backlog'!$C$3:$C$87,MATCH($C37,'Product Backlog'!$A$3:$A$87,0))} -> Crear un estado | E37: {=INDEX('Product Backlog'!$F$3:$F$87,MATCH($C37,'Product Backlog'!$A$3:$A$87,0))} -> 1
C38: HU-054 | D38: {=INDEX('Product Backlog'!$C$3:$C$87,MATCH($C38,'Product Backlog'!$A$3:$A$87,0))} -> Editar un estado | E38: {=INDEX('Product Backlog'!$F$3:$F$87,MATCH($C38,'Product Backlog'!$A$3:$A$87,0))} -> 1
C39: HU-055 | D39: {=INDEX('Product Backlog'!$C$3:$C$87,MATCH($C39,'Product Backlog'!$A$3:$A$87,0))} -> Definir estado inicial y estados finales | E39: {=INDEX('Product Backlog'!$F$3:$F$87,MATCH($C39,'Product Backlog'!$A$3:$A$87,0))} -> 1
C40: HU-057 | D40: {=INDEX('Product Backlog'!$C$3:$C$87,MATCH($C40,'Product Backlog'!$A$3:$A$87,0))} -> Editar una transición | E40: {=INDEX('Product Backlog'!$F$3:$F$87,MATCH($C40,'Product Backlog'!$A$3:$A$87,0))} -> 1
C41: HU-058 | D41: {=INDEX('Product Backlog'!$C$3:$C$87,MATCH($C41,'Product Backlog'!$A$3:$A$87,0))} -> Eliminar una transición | E41: {=INDEX('Product Backlog'!$F$3:$F$87,MATCH($C41,'Product Backlog'!$A$3:$A$87,0))} -> 1
... C50: HU-077 | D50: {=INDEX('Product Backlog'!$C$3:$C$87,MATCH($C50,'Product Backlog'!$A$3:$A$87,0))} -> Visualizar las firmas de un documento | E50: {=INDEX('Product Backlog'!$F$3:$F$87,MATCH($C50,'Product Backlog'!$A$3:$A$87,0))} -> 1
C51: Total SPRINT 2 | E51: =SUM(E29:E50) -> 35
A53: SPRINT 3 | B53: Expediente, plantillas, orígenes/copias y firma electrónica Habilitar el expediente central organizado por área, la generación de documentos desde plantillas, la captura de metadatos extendidos y el manejo de copias (Clase Original/Copia), y la firma electrónica para la aprobación ejecutiva. | C53: HU-022 | D53: {=INDEX('Product Backlog'!$C$3:$C$87,MATCH($C53,'Product Backlog'!$A$3:$A$87,0))} -> Administrar entidades | E53: {=INDEX('Product Backlog'!$F$3:$F$87,MATCH($C53,'Product Backlog'!$A$3:$A$87,0))} -> 1
C54: HU-023 | D54: {=INDEX('Product Backlog'!$C$3:$C$87,MATCH($C54,'Product Backlog'!$A$3:$A$87,0))} -> Listar y filtrar radicados | E54: {=INDEX('Product Backlog'!$F$3:$F$87,MATCH($C54,'Product Backlog'!$A$3:$A$87,0))} -> 2
C55: HU-028 | D55: {=INDEX('Product Backlog'!$C$3:$C$87,MATCH($C55,'Product Backlog'!$A$3:$A$87,0))} -> Visualizar y descargar anexos | E55: {=INDEX('Product Backlog'!$F$3:$F$87,MATCH($C55,'Product Backlog'!$A$3:$A$87,0))} -> 1
C56: HU-043 | D56: {=INDEX('Product Backlog'!$C$3:$C$87,MATCH($C56,'Product Backlog'!$A$3:$A$87,0))} -> Registrar eventos en la bitácora | E56: {=INDEX('Product Backlog'!$F$3:$F$87,MATCH($C56,'Product Backlog'!$A$3:$A$87,0))} -> 3
C57: HU-047 | D57: {=INDEX('Product Backlog'!$C$3:$C$87,MATCH($C57,'Product Backlog'!$A$3:$A$87,0))} -> Filtrar la bitácora por usuario, fecha y acción | E57: {=INDEX('Product Backlog'!$F$3:$F$87,MATCH($C57,'Product Backlog'!$A$3:$A$87,0))} -> 1
C58: HU-048 | D58: {=INDEX('Product Backlog'!$C$3:$C$87,MATCH($C58,'Product Backlog'!$A$3:$A$87,0))} -> Crear un flujo de trabajo | E58: {=INDEX('Product Backlog'!$F$3:$F$87,MATCH($C58,'Product Backlog'!$A$3:$A$87,0))} -> 1
C59: HU-051 | D59: {=INDEX('Product Backlog'!$C$3:$C$87,MATCH($C59,'Product Backlog'!$A$3:$A$87,0))} -> Consultar los flujos de trabajo | E59: {=INDEX('Product Backlog'!$F$3:$F$87,MATCH($C59,'Product Backlog'!$A$3:$A$87,0))} -> 1
C60: HU-056 | D60: {=INDEX('Product Backlog'!$C$3:$C$87,MATCH($C60,'Product Backlog'!$A$3:$A$87,0))} -> Crear una transición | E60: {=INDEX('Product Backlog'!$F$3:$F$87,MATCH($C60,'Product Backlog'!$A$3:$A$87,0))} -> 3
...
